2021-12-14 00:13:31,577 ERROR: Exception on /delete_task/2 [GET] [in /home/harshavardhan/Planner/venv/lib/python3.8/site-packages/flask/app.py:1457]
Traceback (most recent call last):
  File "/home/harshavardhan/Planner/venv/lib/python3.8/site-packages/sqlalchemy/orm/session.py", line 2634, in delete
    state = attributes.instance_state(instance)
AttributeError: 'NoneType' object has no attribute '_sa_instance_state'

The above exception was the direct cause of the following exception:

Traceback (most recent call last):
  File "/home/harshavardhan/Planner/venv/lib/python3.8/site-packages/flask/app.py", line 2073, in wsgi_app
    response = self.full_dispatch_request()
  File "/home/harshavardhan/Planner/venv/lib/python3.8/site-packages/flask/app.py", line 1518, in full_dispatch_request
    rv = self.handle_user_exception(e)
  File "/home/harshavardhan/Planner/venv/lib/python3.8/site-packages/flask/app.py", line 1516, in full_dispatch_request
    rv = self.dispatch_request()
  File "/home/harshavardhan/Planner/venv/lib/python3.8/site-packages/flask/app.py", line 1502, in dispatch_request
    return self.ensure_sync(self.view_functions[rule.endpoint])(**req.view_args)
  File "/home/harshavardhan/Planner/venv/lib/python3.8/site-packages/flask_login/utils.py", line 272, in decorated_view
    return func(*args, **kwargs)
  File "/home/harshavardhan/Planner/Backend/routes.py", line 386, in delete_task
    db.session.delete(t5)
  File "<string>", line 2, in delete
  File "/home/harshavardhan/Planner/venv/lib/python3.8/site-packages/sqlalchemy/orm/session.py", line 2636, in delete
    util.raise_(
  File "/home/harshavardhan/Planner/venv/lib/python3.8/site-packages/sqlalchemy/util/compat.py", line 207, in raise_
    raise exception
sqlalchemy.orm.exc.UnmappedInstanceError: Class 'builtins.NoneType' is not mapped
2021-12-14 00:25:47,706 INFO: Planner App Startup [in /home/harshavardhan/Planner/Backend/__init__.py:45]
2021-12-14 00:25:51,136 ERROR: Exception on /delete_task/2 [GET] [in /home/harshavardhan/Planner/venv/lib/python3.8/site-packages/flask/app.py:1457]
Traceback (most recent call last):
  File "/home/harshavardhan/Planner/venv/lib/python3.8/site-packages/flask/app.py", line 2073, in wsgi_app
    response = self.full_dispatch_request()
  File "/home/harshavardhan/Planner/venv/lib/python3.8/site-packages/flask/app.py", line 1518, in full_dispatch_request
    rv = self.handle_user_exception(e)
  File "/home/harshavardhan/Planner/venv/lib/python3.8/site-packages/flask/app.py", line 1516, in full_dispatch_request
    rv = self.dispatch_request()
  File "/home/harshavardhan/Planner/venv/lib/python3.8/site-packages/flask/app.py", line 1502, in dispatch_request
    return self.ensure_sync(self.view_functions[rule.endpoint])(**req.view_args)
  File "/home/harshavardhan/Planner/venv/lib/python3.8/site-packages/flask_login/utils.py", line 272, in decorated_view
    return func(*args, **kwargs)
  File "/home/harshavardhan/Planner/Backend/routes.py", line 368, in delete_task
    return redirect(url_for('delete_gentk',id))
TypeError: url_for() takes 1 positional argument but 2 were given
2021-12-14 00:26:58,330 INFO: Planner App Startup [in /home/harshavardhan/Planner/Backend/__init__.py:45]
2021-12-14 00:27:03,716 ERROR: Exception on /delete_task/gentk/2 [GET] [in /home/harshavardhan/Planner/venv/lib/python3.8/site-packages/flask/app.py:1457]
Traceback (most recent call last):
  File "/home/harshavardhan/Planner/venv/lib/python3.8/site-packages/flask/app.py", line 2073, in wsgi_app
    response = self.full_dispatch_request()
  File "/home/harshavardhan/Planner/venv/lib/python3.8/site-packages/flask/app.py", line 1518, in full_dispatch_request
    rv = self.handle_user_exception(e)
  File "/home/harshavardhan/Planner/venv/lib/python3.8/site-packages/flask/app.py", line 1516, in full_dispatch_request
    rv = self.dispatch_request()
  File "/home/harshavardhan/Planner/venv/lib/python3.8/site-packages/flask/app.py", line 1502, in dispatch_request
    return self.ensure_sync(self.view_functions[rule.endpoint])(**req.view_args)
  File "/home/harshavardhan/Planner/venv/lib/python3.8/site-packages/flask_login/utils.py", line 272, in decorated_view
    return func(*args, **kwargs)
  File "/home/harshavardhan/Planner/Backend/routes.py", line 428, in delete_gentk
    t = General.query.filter_by(id=task_id).first()
NameError: name 'task_id' is not defined
2021-12-14 00:28:17,370 INFO: Planner App Startup [in /home/harshavardhan/Planner/Backend/__init__.py:45]
<<<<<<< HEAD
2021-12-14 01:44:38,922 INFO: Planner App Startup [in /Users/jayanth/Planner/Backend/__init__.py:45]
=======
2021-12-14 00:33:46,980 INFO: Planner App Startup [in /home/harshavardhan/Planner/Backend/__init__.py:45]
>>>>>>> dev
2021-12-14 14:30:54,402 INFO: Planner App Startup [in /home/harshavardhan/Planner/Backend/__init__.py:45]
2021-12-14 14:42:42,545 INFO: Planner App Startup [in /home/harshavardhan/Planner/Backend/__init__.py:45]
2021-12-14 14:43:13,148 ERROR: Exception on /fullview/7 [GET] [in /home/harshavardhan/Planner/venv/lib/python3.8/site-packages/flask/app.py:1457]
Traceback (most recent call last):
  File "/home/harshavardhan/Planner/venv/lib/python3.8/site-packages/flask/app.py", line 2073, in wsgi_app
    response = self.full_dispatch_request()
  File "/home/harshavardhan/Planner/venv/lib/python3.8/site-packages/flask/app.py", line 1518, in full_dispatch_request
    rv = self.handle_user_exception(e)
  File "/home/harshavardhan/Planner/venv/lib/python3.8/site-packages/flask/app.py", line 1516, in full_dispatch_request
    rv = self.dispatch_request()
  File "/home/harshavardhan/Planner/venv/lib/python3.8/site-packages/flask/app.py", line 1502, in dispatch_request
    return self.ensure_sync(self.view_functions[rule.endpoint])(**req.view_args)
  File "/home/harshavardhan/Planner/venv/lib/python3.8/site-packages/flask_login/utils.py", line 272, in decorated_view
    return func(*args, **kwargs)
  File "/home/harshavardhan/Planner/Backend/routes.py", line 466, in fullview
    return render_template('fullview.html', task=task, t2=t2)
  File "/home/harshavardhan/Planner/venv/lib/python3.8/site-packages/flask/templating.py", line 147, in render_template
    return _render(
  File "/home/harshavardhan/Planner/venv/lib/python3.8/site-packages/flask/templating.py", line 128, in _render
    rv = template.render(context)
  File "/home/harshavardhan/Planner/venv/lib/python3.8/site-packages/jinja2/environment.py", line 1291, in render
    self.environment.handle_exception()
  File "/home/harshavardhan/Planner/venv/lib/python3.8/site-packages/jinja2/environment.py", line 925, in handle_exception
    raise rewrite_traceback_stack(source=source)
  File "/home/harshavardhan/Planner/Backend/templates/fullview.html", line 1, in top-level template code
    {% extends "base.html" %}
  File "/home/harshavardhan/Planner/Backend/templates/base.html", line 97, in top-level template code
    {% block content %}{% endblock %}
  File "/home/harshavardhan/Planner/Backend/templates/fullview.html", line 99, in block 'content'
    <p><a href="{{ t1.link }}" class="card-text btn btn-outline-primary">meeting link</a></p>
  File "/home/harshavardhan/Planner/venv/lib/python3.8/site-packages/jinja2/environment.py", line 474, in getattr
    return getattr(obj, attribute)
jinja2.exceptions.UndefinedError: 't1' is undefined
2021-12-14 14:45:07,338 INFO: Planner App Startup [in /home/harshavardhan/Planner/Backend/__init__.py:45]
