2021-12-13 13:45:09,759 INFO: Planner App Startup [in /home/harshavardhan/Planner/Backend/__init__.py:43]
2021-12-13 13:48:03,342 INFO: Planner App Startup [in /home/harshavardhan/Planner/Backend/__init__.py:43]
2021-12-13 13:49:47,415 INFO: Planner App Startup [in /home/harshavardhan/Planner/Backend/__init__.py:43]
2021-12-13 13:53:58,128 INFO: Planner App Startup [in /home/harshavardhan/Planner/Backend/__init__.py:43]
2021-12-13 13:54:22,241 ERROR: Exception on /index/projects [POST] [in /home/harshavardhan/Planner/venv/lib/python3.8/site-packages/flask/app.py:1457]
Traceback (most recent call last):
  File "/home/harshavardhan/Planner/venv/lib/python3.8/site-packages/flask/app.py", line 2073, in wsgi_app
    response = self.full_dispatch_request()
  File "/home/harshavardhan/Planner/venv/lib/python3.8/site-packages/flask/app.py", line 1518, in full_dispatch_request
    rv = self.handle_user_exception(e)
  File "/home/harshavardhan/Planner/venv/lib/python3.8/site-packages/flask/app.py", line 1516, in full_dispatch_request
    rv = self.dispatch_request()
  File "/home/harshavardhan/Planner/venv/lib/python3.8/site-packages/flask/app.py", line 1502, in dispatch_request
    return self.ensure_sync(self.view_functions[rule.endpoint])(**req.view_args)
  File "/home/harshavardhan/Planner/venv/lib/python3.8/site-packages/flask_login/utils.py", line 272, in decorated_view
    return func(*args, **kwargs)
  File "/home/harshavardhan/Planner/Backend/routes.py", line 67, in projects
    return redirect(url_for('travel'))
  File "/home/harshavardhan/Planner/venv/lib/python3.8/site-packages/flask/helpers.py", line 338, in url_for
    return appctx.app.handle_url_build_error(error, endpoint, values)
  File "/home/harshavardhan/Planner/venv/lib/python3.8/site-packages/flask/helpers.py", line 325, in url_for
    rv = url_adapter.build(
  File "/home/harshavardhan/Planner/venv/lib/python3.8/site-packages/werkzeug/routing.py", line 2314, in build
    raise BuildError(endpoint, values, method, self)
werkzeug.routing.BuildError: Could not build url for endpoint 'travel'. Did you forget to specify values ['task_id']?
2021-12-13 13:54:30,769 ERROR: Exception on /index/projects [POST] [in /home/harshavardhan/Planner/venv/lib/python3.8/site-packages/flask/app.py:1457]
Traceback (most recent call last):
  File "/home/harshavardhan/Planner/venv/lib/python3.8/site-packages/flask/app.py", line 2073, in wsgi_app
    response = self.full_dispatch_request()
  File "/home/harshavardhan/Planner/venv/lib/python3.8/site-packages/flask/app.py", line 1518, in full_dispatch_request
    rv = self.handle_user_exception(e)
  File "/home/harshavardhan/Planner/venv/lib/python3.8/site-packages/flask/app.py", line 1516, in full_dispatch_request
    rv = self.dispatch_request()
  File "/home/harshavardhan/Planner/venv/lib/python3.8/site-packages/flask/app.py", line 1502, in dispatch_request
    return self.ensure_sync(self.view_functions[rule.endpoint])(**req.view_args)
  File "/home/harshavardhan/Planner/venv/lib/python3.8/site-packages/flask_login/utils.py", line 272, in decorated_view
    return func(*args, **kwargs)
  File "/home/harshavardhan/Planner/Backend/routes.py", line 67, in projects
    return redirect(url_for('travel'))
  File "/home/harshavardhan/Planner/venv/lib/python3.8/site-packages/flask/helpers.py", line 338, in url_for
    return appctx.app.handle_url_build_error(error, endpoint, values)
  File "/home/harshavardhan/Planner/venv/lib/python3.8/site-packages/flask/helpers.py", line 325, in url_for
    rv = url_adapter.build(
  File "/home/harshavardhan/Planner/venv/lib/python3.8/site-packages/werkzeug/routing.py", line 2314, in build
    raise BuildError(endpoint, values, method, self)
werkzeug.routing.BuildError: Could not build url for endpoint 'travel'. Did you forget to specify values ['task_id']?
2021-12-13 13:56:13,609 INFO: Planner App Startup [in /home/harshavardhan/Planner/Backend/__init__.py:43]
2021-12-13 13:57:52,277 INFO: Planner App Startup [in /home/harshavardhan/Planner/Backend/__init__.py:43]
2021-12-13 13:59:19,303 ERROR: Exception on /edit_task/travel/3 [POST] [in /home/harshavardhan/Planner/venv/lib/python3.8/site-packages/flask/app.py:1457]
Traceback (most recent call last):
  File "/home/harshavardhan/Planner/venv/lib/python3.8/site-packages/flask/app.py", line 2073, in wsgi_app
    response = self.full_dispatch_request()
  File "/home/harshavardhan/Planner/venv/lib/python3.8/site-packages/flask/app.py", line 1518, in full_dispatch_request
    rv = self.handle_user_exception(e)
  File "/home/harshavardhan/Planner/venv/lib/python3.8/site-packages/flask/app.py", line 1516, in full_dispatch_request
    rv = self.dispatch_request()
  File "/home/harshavardhan/Planner/venv/lib/python3.8/site-packages/flask/app.py", line 1502, in dispatch_request
    return self.ensure_sync(self.view_functions[rule.endpoint])(**req.view_args)
  File "/home/harshavardhan/Planner/venv/lib/python3.8/site-packages/flask_login/utils.py", line 272, in decorated_view
    return func(*args, **kwargs)
  File "/home/harshavardhan/Planner/Backend/routes.py", line 327, in travel
    t = Travel(parent3=task, start_date=form.start_date.data, finish_date=form.finish_date.data, source=form.source.data, destination=destination.source.data)
NameError: name 'destination' is not defined
2021-12-13 14:00:28,255 INFO: Planner App Startup [in /home/harshavardhan/Planner/Backend/__init__.py:43]
2021-12-13 14:11:25,175 INFO: Planner App Startup [in /home/harshavardhan/Planner/Backend/__init__.py:43]
2021-12-13 14:13:57,231 INFO: Planner App Startup [in /home/harshavardhan/Planner/Backend/__init__.py:43]
2021-12-13 14:18:50,557 INFO: Planner App Startup [in /home/harshavardhan/Planner/Backend/__init__.py:43]
2021-12-13 14:19:09,092 INFO: Planner App Startup [in /home/harshavardhan/Planner/Backend/__init__.py:43]
